Workbook

Sheet Nextt
D2: Cadastre vários itens simultaneamente
D3: Preencha os dados do que quiser cadastrar.
B7: Categorias: | G7: Envie a planilha Excel
B9: Cadastro de Produtos
B10: Cadastro de Pedidos | H10: Ao terminar, lembre-se de salvar e importar a planilha Excel para o Matriz
B11: Cadastro de Marcas

Sheet Cadastro de Produtos
A1: Cadastros Básicos > Produto | Q1: Atributos | Y1: Banco de Dados
A2: Cadastro de Produtos
A3: Seção | B3: Espécie | C3: Descrição | D3: Descrição Reduzida | E3: Marca | F3: Referência do Fornecedor | G3: Código Original | H3: Comprador | I3: Produto Ativo? | J3: Unidade | K3: Classificação Fiscal | L3: Origem | M3: Valor de Venda | N3: % ICMS | O3: % IPI | P3: Etiqueta Padrão | Y3: Seção | Z3: Espécie | AA3: Marca | AB3: Comprador | AC3: Unidade | AD3: Etiqueta Padrão
A4: Obrigatório | B4: Obrigatório | C4: Obrigatório | D4: Obrigatório | E4: Obrigatório | F4: Obrigatório | H4: Obrigatório | J4: Obrigatório | K4: Obrigatório | L4: Obrigatório | M4: Obrigatório | P4: Obrigatório
A5: Aviso: Os valores de "seção" são importados automaticamente do banco de dados do Matriz. | B5: Aviso: Os valores de "espécie" são importados automaticamente do banco de dados do Matriz. | C5: Máximo 50 caracteres. Dica: Se a sua descrição incluir os mesmos valores de "seção" e/ou "espécie", remova as palavras repetidas para evitar duplicidade na impressão da etiqueta. | D5: Máximo 50 caracteres. Dica: A "descrição reduzida" geralmente inclui apenas uma ou duas palavras-chave relacionadas à "descrição". | E5: Aviso: Os valores de "marca" são importados automaticamente do banco de dados do Matriz. | H5: Aviso: Os valores de "comprador" são importados automaticamente do banco de dados do Matriz. | P5: Aviso: Os valores de "etiqueta padrão" são importados automaticamente do banco de dados do Matriz.
A6: 1 - BEBE | B6: 1 - MACACAO | C6: teste | D6: testeee | E6: 4 - ADG CONFECCOES | F6: ref1 | H6: 6 - ERIK WALLISON | I6: 1 | J6: 3 - PAR | K6: 5203 | L6: 0 | M6: 100 | N6: 0 | O6: 0 | P6: 5 - Remarcacao Zebra | Y6: =INT(INDEX('Dados Consolidados'!$R$2:$R$38, MATCH(A6, 'Dados Consolidados'!$A$2:$A$38, 0))) -> 1 | Z6: =INT(INDEX('Dados Consolidados'!$S$2:$S$38, MATCH(B6, 'Dados Consolidados'!$B$2:$B$38, 0))) -> 1 | AA6: =INT(INDEX('Dados Consolidados'!$T$2:$T$38, MATCH(E6, 'Dados Consolidados'!$E$2:$E$38, 0))) -> 4 | AB6: =INT(INDEX('Dados Consolidados'!$U$2:$U$38, MATCH(H6, 'Dados Consolidados'!$H$2:$H$38, 0))) -> 6 | AC6: =INT(INDEX('Dados Consolidados'!$V$2:$V$38, MATCH(J6, 'Dados Consolidados'!$J$2:$J$38, 0))) -> 3 | AD6: =INT(INDEX('Dados Consolidados'!$W$2:$W$38, MATCH(P6, 'Dados Consolidados'!$P$2:$P$38, 0))) -> 5
A7: 1 - BEBE | B7: 1 - MACACAO | C7: teste | D7: testeee | E7: 4 - ADG CONFECCOES | F7: ref2 | H7: 6 - ERIK WALLISON | I7: 1 | J7: 3 - PAR | K7: 5203 | L7: 0 | M7: 100 | N7: 0 | O7: 0 | P7: 5 - Remarcacao Zebra | Y7: =INT(INDEX('Dados Consolidados'!$R$2:$R$38, MATCH(A7, 'Dados Consolidados'!$A$2:$A$38, 0))) -> 1 | Z7: =INT(INDEX('Dados Consolidados'!$S$2:$S$38, MATCH(B7, 'Dados Consolidados'!$B$2:$B$38, 0))) -> 1 | AA7: =INT(INDEX('Dados Consolidados'!$T$2:$T$38, MATCH(E7, 'Dados Consolidados'!$E$2:$E$38, 0))) -> 4 | AB7: =INT(INDEX('Dados Consolidados'!$U$2:$U$38, MATCH(H7, 'Dados Consolidados'!$H$2:$H$38, 0))) -> 6 | AC7: =INT(INDEX('Dados Consolidados'!$V$2:$V$38, MATCH(J7, 'Dados Consolidados'!$J$2:$J$38, 0))) -> 3 | AD7: =INT(INDEX('Dados Consolidados'!$W$2:$W$38, MATCH(P7, 'Dados Consolidados'!$P$2:$P$38, 0))) -> 5
A8: 1 - BEBE | B8: 1 - MACACAO | C8: teste | D8: testeee | E8: 4 - ADG CONFECCOES | F8: ref3 | H8: 6 - ERIK WALLISON | I8: 1 | J8: 3 - PAR | K8: 5203 | L8: 0 | M8: 100 | N8: 0 | O8: 0 | P8: 5 - Remarcacao Zebra | Y8: =INT(INDEX('Dados Consolidados'!$R$2:$R$38, MATCH(A8, 'Dados Consolidados'!$A$2:$A$38, 0))) -> 1 | Z8: =INT(INDEX('Dados Consolidados'!$S$2:$S$38, MATCH(B8, 'Dados Consolidados'!$B$2:$B$38, 0))) -> 1 | AA8: =INT(INDEX('Dados Consolidados'!$T$2:$T$38, MATCH(E8, 'Dados Consolidados'!$E$2:$E$38, 0))) -> 4 | AB8: =INT(INDEX('Dados Consolidados'!$U$2:$U$38, MATCH(H8, 'Dados Consolidados'!$H$2:$H$38, 0))) -> 6 | AC8: =INT(INDEX('Dados Consolidados'!$V$2:$V$38, MATCH(J8, 'Dados Consolidados'!$J$2:$J$38, 0))) -> 3 | AD8: =INT(INDEX('Dados Consolidados'!$W$2:$W$38, MATCH(P8, 'Dados Consolidados'!$P$2:$P$38, 0))) -> 5
A9: 1 - BEBE | B9: 1 - MACACAO | C9: teste | D9: testeee | E9: 4 - ADG CONFECCOES | F9: ref4 | H9: 6 - ERIK WALLISON | I9: 1 | J9: 3 - PAR | K9: 5203 | L9: 0 | M9: 100 | N9: 0 | O9: 0 | P9: 5 - Remarcacao Zebra | Y9: =INT(INDEX('Dados Consolidados'!$R$2:$R$38, MATCH(A9, 'Dados Consolidados'!$A$2:$A$38, 0))) -> 1 | Z9: =INT(INDEX('Dados Consolidados'!$S$2:$S$38, MATCH(B9, 'Dados Consolidados'!$B$2:$B$38, 0))) -> 1 | AA9: =INT(INDEX('Dados Consolidados'!$T$2:$T$38, MATCH(E9, 'Dados Consolidados'!$E$2:$E$38, 0))) -> 4 | AB9: =INT(INDEX('Dados Consolidados'!$U$2:$U$38, MATCH(H9, 'Dados Consolidados'!$H$2:$H$38, 0))) -> 6 | AC9: =INT(INDEX('Dados Consolidados'!$V$2:$V$38, MATCH(J9, 'Dados Consolidados'!$J$2:$J$38, 0))) -> 3 | AD9: =INT(INDEX('Dados Consolidados'!$W$2:$W$38, MATCH(P9, 'Dados Consolidados'!$P$2:$P$38, 0))) -> 5
A10: 1 - BEBE | B10: 1 - MACACAO | C10: teste | D10: testeee | E10: 4 - ADG CONFECCOES | F10: ref5 | H10: 6 - ERIK WALLISON | I10: 1 | J10: 3 - PAR | K10: 5203 | L10: 0 | M10: 100 | N10: 0 | O10: 0 | P10: 5 - Remarcacao Zebra | Y10: =INT(INDEX('Dados Consolidados'!$R$2:$R$38, MATCH(A10, 'Dados Consolidados'!$A$2:$A$38, 0))) -> 1 | Z10: =INT(INDEX('Dados Consolidados'!$S$2:$S$38, MATCH(B10, 'Dados Consolidados'!$B$2:$B$38, 0))) -> 1 | AA10: =INT(INDEX('Dados Consolidados'!$T$2:$T$38, MATCH(E10, 'Dados Consolidados'!$E$2:$E$38, 0))) -> 4 | AB10: =INT(INDEX('Dados Consolidados'!$U$2:$U$38, MATCH(H10, 'Dados Consolidados'!$H$2:$H$38, 0))) -> 6 | AC10: =INT(INDEX('Dados Consolidados'!$V$2:$V$38, MATCH(J10, 'Dados Consolidados'!$J$2:$J$38, 0))) -> 3 | AD10: =INT(INDEX('Dados Consolidados'!$W$2:$W$38, MATCH(P10, 'Dados Consolidados'!$P$2:$P$38, 0))) -> 5
A11: 1 - BEBE | B11: 1 - MACACAO | C11: teste | D11: testeee | E11: 4 - ADG CONFECCOES | F11: ref6 | H11: 6 - ERIK WALLISON | I11: 1 | J11: 3 - PAR | K11: 5203 | L11: 0 | M11: 100 | N11: 0 | O11: 0 | P11: 5 - Remarcacao Zebra | Y11: =INT(INDEX('Dados Consolidados'!$R$2:$R$38, MATCH(A11, 'Dados Consolidados'!$A$2:$A$38, 0))) -> 1 | Z11: =INT(INDEX('Dados Consolidados'!$S$2:$S$38, MATCH(B11, 'Dados Consolidados'!$B$2:$B$38, 0))) -> 1 | AA11: =INT(INDEX('Dados Consolidados'!$T$2:$T$38, MATCH(E11, 'Dados Consolidados'!$E$2:$E$38, 0))) -> 4 | AB11: =INT(INDEX('Dados Consolidados'!$U$2:$U$38, MATCH(H11, 'Dados Consolidados'!$H$2:$H$38, 0))) -> 6 | AC11: =INT(INDEX('Dados Consolidados'!$V$2:$V$38, MATCH(J11, 'Dados Consolidados'!$J$2:$J$38, 0))) -> 3 | AD11: =INT(INDEX('Dados Consolidados'!$W$2:$W$38, MATCH(P11, 'Dados Consolidados'!$P$2:$P$38, 0))) -> 5
A12: 1 - BEBE | B12: 1 - MACACAO | C12: teste | D12: testeee | E12: 4 - ADG CONFECCOES | F12: ref7 | H12: 6 - ERIK WALLISON | I12: 1 | J12: 3 - PAR | K12: 5203 | L12: 0 | M12: 100 | N12: 0 | O12: 0 | P12: 5 - Remarcacao Zebra | Y12: =INT(INDEX('Dados Consolidados'!$R$2:$R$38, MATCH(A12, 'Dados Consolidados'!$A$2:$A$38, 0))) -> 1 | Z12: =INT(INDEX('Dados Consolidados'!$S$2:$S$38, MATCH(B12, 'Dados Consolidados'!$B$2:$B$38, 0))) -> 1 | AA12: =INT(INDEX('Dados Consolidados'!$T$2:$T$38, MATCH(E12, 'Dados Consolidados'!$E$2:$E$38, 0))) -> 4 | AB12: =INT(INDEX('Dados Consolidados'!$U$2:$U$38, MATCH(H12, 'Dados Consolidados'!$H$2:$H$38, 0))) -> 6 | AC12: =INT(INDEX('Dados Consolidados'!$V$2:$V$38, MATCH(J12, 'Dados Consolidados'!$J$2:$J$38, 0))) -> 3 | AD12: =INT(INDEX('Dados Consolidados'!$W$2:$W$38, MATCH(P12, 'Dados Consolidados'!$P$2:$P$38, 0))) -> 5
A13: 1 - BEBE | B13: 1 - MACACAO | C13: teste | D13: testeee | E13: 4 - ADG CONFECCOES | F13: ref8 | H13: 6 - ERIK WALLISON | I13: 1 | J13: 3 - PAR | K13: 5203 | L13: 0 | M13: 100 | N13: 0 | O13: 0 | P13: 5 - Remarcacao Zebra | Y13: =INT(INDEX('Dados Consolidados'!$R$2:$R$38, MATCH(A13, 'Dados Consolidados'!$A$2:$A$38, 0))) -> 1 | Z13: =INT(INDEX('Dados Consolidados'!$S$2:$S$38, MATCH(B13, 'Dados Consolidados'!$B$2:$B$38, 0))) -> 1 | AA13: =INT(INDEX('Dados Consolidados'!$T$2:$T$38, MATCH(E13, 'Dados Consolidados'!$E$2:$E$38, 0))) -> 4 | AB13: =INT(INDEX('Dados Consolidados'!$U$2:$U$38, MATCH(H13, 'Dados Consolidados'!$H$2:$H$38, 0))) -> 6 | AC13: =INT(INDEX('Dados Consolidados'!$V$2:$V$38, MATCH(J13, 'Dados Consolidados'!$J$2:$J$38, 0))) -> 3 | AD13: =INT(INDEX('Dados Consolidados'!$W$2:$W$38, MATCH(P13, 'Dados Consolidados'!$P$2:$P$38, 0))) -> 5
A14: 1 - BEBE | B14: 1 - MACACAO | C14: teste | D14: testeee | E14: 4 - ADG CONFECCOES | F14: ref9 | H14: 6 - ERIK WALLISON | I14: 1 | J14: 3 - PAR | K14: 5203 | L14: 0 | M14: 100 | N14: 0 | O14: 0 | P14: 5 - Remarcacao Zebra | Y14: =INT(INDEX('Dados Consolidados'!$R$2:$R$38, MATCH(A14, 'Dados Consolidados'!$A$2:$A$38, 0))) -> 1 | Z14: =INT(INDEX('Dados Consolidados'!$S$2:$S$38, MATCH(B14, 'Dados Consolidados'!$B$2:$B$38, 0))) -> 1 | AA14: =INT(INDEX('Dados Consolidados'!$T$2:$T$38, MATCH(E14, 'Dados Consolidados'!$E$2:$E$38, 0))) -> 4 | AB14: =INT(INDEX('Dados Consolidados'!$U$2:$U$38, MATCH(H14, 'Dados Consolidados'!$H$2:$H$38, 0))) -> 6 | AC14: =INT(INDEX('Dados Consolidados'!$V$2:$V$38, MATCH(J14, 'Dados Consolidados'!$J$2:$J$38, 0))) -> 3 | AD14: =INT(INDEX('Dados Consolidados'!$W$2:$W$38, MATCH(P14, 'Dados Consolidados'!$P$2:$P$38, 0))) -> 5
A15: 1 - BEBE | B15: 1 - MACACAO | C15: teste | D15: testeee | E15: 4 - ADG CONFECCOES | F15: ref10 | H15: 6 - ERIK WALLISON | I15: 1 | J15: 3 - PAR | K15: 5203 | L15: 0 | M15: 100 | N15: 0 | O15: 0 | P15: 5 - Remarcacao Zebra | Y15: =INT(INDEX('Dados Consolidados'!$R$2:$R$38, MATCH(A15, 'Dados Consolidados'!$A$2:$A$38, 0))) -> 1 | Z15: =INT(INDEX('Dados Consolidados'!$S$2:$S$38, MATCH(B15, 'Dados Consolidados'!$B$2:$B$38, 0))) -> 1 | AA15: =INT(INDEX('Dados Consolidados'!$T$2:$T$38, MATCH(E15, 'Dados Consolidados'!$E$2:$E$38, 0))) -> 4 | AB15: =INT(INDEX('Dados Consolidados'!$U$2:$U$38, MATCH(H15, 'Dados Consolidados'!$H$2:$H$38, 0))) -> 6 | AC15: =INT(INDEX('Dados Consolidados'!$V$2:$V$38, MATCH(J15, 'Dados Consolidados'!$J$2:$J$38, 0))) -> 3 | AD15: =INT(INDEX('Dados Consolidados'!$W$2:$W$38, MATCH(P15, 'Dados Consolidados'!$P$2:$P$38, 0))) -> 5
A16: 1 - BEBE | B16: 1 - MACACAO | C16: teste | D16: testeee | E16: 4 - ADG CONFECCOES | F16: ref11 | H16: 6 - ERIK WALLISON | I16: 1 | J16: 3 - PAR | K16: 5203 | L16: 0 | M16: 100 | N16: 0 | O16: 0 | P16: 5 - Remarcacao Zebra | Y16: =INT(INDEX('Dados Consolidados'!$R$2:$R$38, MATCH(A16, 'Dados Consolidados'!$A$2:$A$38, 0))) -> 1 | Z16: =INT(INDEX('Dados Consolidados'!$S$2:$S$38, MATCH(B16, 'Dados Consolidados'!$B$2:$B$38, 0))) -> 1 | AA16: =INT(INDEX('Dados Consolidados'!$T$2:$T$38, MATCH(E16, 'Dados Consolidados'!$E$2:$E$38, 0))) -> 4 | AB16: =INT(INDEX('Dados Consolidados'!$U$2:$U$38, MATCH(H16, 'Dados Consolidados'!$H$2:$H$38, 0))) -> 6 | AC16: =INT(INDEX('Dados Consolidados'!$V$2:$V$38, MATCH(J16, 'Dados Consolidados'!$J$2:$J$38, 0))) -> 3 | AD16: =INT(INDEX('Dados Consolidados'!$W$2:$W$38, MATCH(P16, 'Dados Consolidados'!$P$2:$P$38, 0))) -> 5
Y17: =INT(INDEX('Dados Consolidados'!$R$2:$R$38, MATCH(A17, 'Dados Consolidados'!$A$2:$A$38, 0))) -> #N/A | Z17: =INT(INDEX('Dados Consolidados'!$S$2:$S$38, MATCH(B17, 'Dados Consolidados'!$B$2:$B$38, 0))) -> #N/A | AA17: =INT(INDEX('Dados Consolidados'!$T$2:$T$38, MATCH(E17, 'Dados Consolidados'!$E$2:$E$38, 0))) -> #N/A | AB17: =INT(INDEX('Dados Consolidados'!$U$2:$U$38, MATCH(H17, 'Dados Consolidados'!$H$2:$H$38, 0))) -> #N/A | AC17: =INT(INDEX('Dados Consolidados'!$V$2:$V$38, MATCH(J17, 'Dados Consolidados'!$J$2:$J$38, 0))) -> #N/A | AD17: =INT(INDEX('Dados Consolidados'!$W$2:$W$38, MATCH(P17, 'Dados Consolidados'!$P$2:$P$38, 0))) -> #N/A
Y18: =INT(INDEX('Dados Consolidados'!$R$2:$R$38, MATCH(A18, 'Dados Consolidados'!$A$2:$A$38, 0))) -> #N/A | Z18: =INT(INDEX('Dados Consolidados'!$S$2:$S$38, MATCH(B18, 'Dados Consolidados'!$B$2:$B$38, 0))) -> #N/A | AA18: =INT(INDEX('Dados Consolidados'!$T$2:$T$38, MATCH(E18, 'Dados Consolidados'!$E$2:$E$38, 0))) -> #N/A | AB18: =INT(INDEX('Dados Consolidados'!$U$2:$U$38, MATCH(H18, 'Dados Consolidados'!$H$2:$H$38, 0))) -> #N/A | AC18: =INT(INDEX('Dados Consolidados'!$V$2:$V$38, MATCH(J18, 'Dados Consolidados'!$J$2:$J$38, 0))) -> #N/A | AD18: =INT(INDEX('Dados Consolidados'!$W$2:$W$38, MATCH(P18, 'Dados Consolidados'!$P$2:$P$38, 0))) -> #N/A
Y19: =INT(INDEX('Dados Consolidados'!$R$2:$R$38, MATCH(A19, 'Dados Consolidados'!$A$2:$A$38, 0))) -> #N/A | Z19: =INT(INDEX('Dados Consolidados'!$S$2:$S$38, MATCH(B19, 'Dados Consolidados'!$B$2:$B$38, 0))) -> #N/A | AA19: =INT(INDEX('Dados Consolidados'!$T$2:$T$38, MATCH(E19, 'Dados Consolidados'!$E$2:$E$38, 0))) -> #N/A | AB19: =INT(INDEX('Dados Consolidados'!$U$2:$U$38, MATCH(H19, 'Dados Consolidados'!$H$2:$H$38, 0))) -> #N/A | AC19: =INT(INDEX('Dados Consolidados'!$V$2:$V$38, MATCH(J19, 'Dados Consolidados'!$J$2:$J$38, 0))) -> #N/A | AD19: =INT(INDEX('Dados Consolidados'!$W$2:$W$38, MATCH(P19, 'Dados Consolidados'!$P$2:$P$38, 0))) -> #N/A
Y20: =INT(INDEX('Dados Consolidados'!$R$2:$R$38, MATCH(A20, 'Dados Consolidados'!$A$2:$A$38, 0))) -> #N/A | Z20: =INT(INDEX('Dados Consolidados'!$S$2:$S$38, MATCH(B20, 'Dados Consolidados'!$B$2:$B$38, 0))) -> #N/A | AA20: =INT(INDEX('Dados Consolidados'!$T$2:$T$38, MATCH(E20, 'Dados Consolidados'!$E$2:$E$38, 0))) -> #N/A | AB20: =INT(INDEX('Dados Consolidados'!$U$2:$U$38, MATCH(H20, 'Dados Consolidados'!$H$2:$H$38, 0))) -> #N/A | AC20: =INT(INDEX('Dados Consolidados'!$V$2:$V$38, MATCH(J20, 'Dados Consolidados'!$J$2:$J$38, 0))) -> #N/A | AD20: =INT(INDEX('Dados Consolidados'!$W$2:$W$38, MATCH(P20, 'Dados Consolidados'!$P$2:$P$38, 0))) -> #N/A
Y21: =INT(INDEX('Dados Consolidados'!$R$2:$R$38, MATCH(A21, 'Dados Consolidados'!$A$2:$A$38, 0))) -> #N/A | Z21: =INT(INDEX('Dados Consolidados'!$S$2:$S$38, MATCH(B21, 'Dados Consolidados'!$B$2:$B$38, 0))) -> #N/A | AA21: =INT(INDEX('Dados Consolidados'!$T$2:$T$38, MATCH(E21, 'Dados Consolidados'!$E$2:$E$38, 0))) -> #N/A | AB21: =INT(INDEX('Dados Consolidados'!$U$2:$U$38, MATCH(H21, 'Dados Consolidados'!$H$2:$H$38, 0))) -> #N/A | AC21: =INT(INDEX('Dados Consolidados'!$V$2:$V$38, MATCH(J21, 'Dados Consolidados'!$J$2:$J$38, 0))) -> #N/A | AD21: =INT(INDEX('Dados Consolidados'!$W$2:$W$38, MATCH(P21, 'Dados Consolidados'!$P$2:$P$38, 0))) -> #N/A
Y22: =INT(INDEX('Dados Consolidados'!$R$2:$R$38, MATCH(A22, 'Dados Consolidados'!$A$2:$A$38, 0))) -> #N/A | Z22: =INT(INDEX('Dados Consolidados'!$S$2:$S$38, MATCH(B22, 'Dados Consolidados'!$B$2:$B$38, 0))) -> #N/A | AA22: =INT(INDEX('Dados Consolidados'!$T$2:$T$38, MATCH(E22, 'Dados Consolidados'!$E$2:$E$38, 0))) -> #N/A | AB22: =INT(INDEX('Dados Consolidados'!$U$2:$U$38, MATCH(H22, 'Dados Consolidados'!$H$2:$H$38, 0))) -> #N/A | AC22: =INT(INDEX('Dados Consolidados'!$V$2:$V$38, MATCH(J22, 'Dados Consolidados'!$J$2:$J$38, 0))) -> #N/A | AD22: =INT(INDEX('Dados Consolidados'!$W$2:$W$38, MATCH(P22, 'Dados Consolidados'!$P$2:$P$38, 0))) -> #N/A
Y23: =INT(INDEX('Dados Consolidados'!$R$2:$R$38, MATCH(A23, 'Dados Consolidados'!$A$2:$A$38, 0))) -> #N/A | Z23: =INT(INDEX('Dados Consolidados'!$S$2:$S$38, MATCH(B23, 'Dados Consolidados'!$B$2:$B$38, 0))) -> #N/A | AA23: =INT(INDEX('Dados Consolidados'!$T$2:$T$38, MATCH(E23, 'Dados Consolidados'!$E$2:$E$38, 0))) -> #N/A | AB23: =INT(INDEX('Dados Consolidados'!$U$2:$U$38, MATCH(H23, 'Dados Consolidados'!$H$2:$H$38, 0))) -> #N/A | AC23: =INT(INDEX('Dados Consolidados'!$V$2:$V$38, MATCH(J23, 'Dados Consolidados'!$J$2:$J$38, 0))) -> #N/A | AD23: =INT(INDEX('Dados Consolidados'!$W$2:$W$38, MATCH(P23, 'Dados Consolidados'!$P$2:$P$38, 0))) -> #N/A
Y24: =INT(INDEX('Dados Consolidados'!$R$2:$R$38, MATCH(A24, 'Dados Consolidados'!$A$2:$A$38, 0))) -> #N/A | Z24: =INT(INDEX('Dados Consolidados'!$S$2:$S$38, MATCH(B24, 'Dados Consolidados'!$B$2:$B$38, 0))) -> #N/A | AA24: =INT(INDEX('Dados Consolidados'!$T$2:$T$38, MATCH(E24, 'Dados Consolidados'!$E$2:$E$38, 0))) -> #N/A | AB24: =INT(INDEX('Dados Consolidados'!$U$2:$U$38, MATCH(H24, 'Dados Consolidados'!$H$2:$H$38, 0))) -> #N/A | AC24: =INT(INDEX('Dados Consolidados'!$V$2:$V$38, MATCH(J24, 'Dados Consolidados'!$J$2:$J$38, 0))) -> #N/A | AD24: =INT(INDEX('Dados Consolidados'!$W$2:$W$38, MATCH(P24, 'Dados Consolidados'!$P$2:$P$38, 0))) -> #N/A
Y25: =INT(INDEX('Dados Consolidados'!$R$2:$R$38, MATCH(A25, 'Dados Consolidados'!$A$2:$A$38, 0))) -> #N/A | Z25: =INT(INDEX('Dados Consolidados'!$S$2:$S$38, MATCH(B25, 'Dados Consolidados'!$B$2:$B$38, 0))) -> #N/A | AA25: =INT(INDEX('Dados Consolidados'!$T$2:$T$38, MATCH(E25, 'Dados Consolidados'!$E$2:$E$38, 0))) -> #N/A | AB25: =INT(INDEX('Dados Consolidados'!$U$2:$U$38, MATCH(H25, 'Dados Consolidados'!$H$2:$H$38, 0))) -> #N/A | AC25: =INT(INDEX('Dados Consolidados'!$V$2:$V$38, MATCH(J25, 'Dados Consolidados'!$J$2:$J$38, 0))) -> #N/A | AD25: =INT(INDEX('Dados Consolidados'!$W$2:$W$38, MATCH(P25, 'Dados Consolidados'!$P$2:$P$38, 0))) -> #N/A
Y26: =INT(INDEX('Dados Consolidados'!$R$2:$R$38, MATCH(A26, 'Dados Consolidados'!$A$2:$A$38, 0))) -> #N/A | Z26: =INT(INDEX('Dados Consolidados'!$S$2:$S$38, MATCH(B26, 'Dados Consolidados'!$B$2:$B$38, 0))) -> #N/A | AA26: =INT(INDEX('Dados Consolidados'!$T$2:$T$38, MATCH(E26, 'Dados Consolidados'!$E$2:$E$38, 0))) -> #N/A | AB26: =INT(INDEX('Dados Consolidados'!$U$2:$U$38, MATCH(H26, 'Dados Consolidados'!$H$2:$H$38, 0))) -> #N/A | AC26: =INT(INDEX('Dados Consolidados'!$V$2:$V$38, MATCH(J26, 'Dados Consolidados'!$J$2:$J$38, 0))) -> #N/A | AD26: =INT(INDEX('Dados Consolidados'!$W$2:$W$38, MATCH(P26, 'Dados Consolidados'!$P$2:$P$38, 0))) -> #N/A
Y27: =INT(INDEX('Dados Consolidados'!$R$2:$R$38, MATCH(A27, 'Dados Consolidados'!$A$2:$A$38, 0))) -> #N/A | Z27: =INT(INDEX('Dados Consolidados'!$S$2:$S$38, MATCH(B27, 'Dados Consolidados'!$B$2:$B$38, 0))) -> #N/A | AA27: =INT(INDEX('Dados Consolidados'!$T$2:$T$38, MATCH(E27, 'Dados Consolidados'!$E$2:$E$38, 0))) -> #N/A | AB27: =INT(INDEX('Dados Consolidados'!$U$2:$U$38, MATCH(H27, 'Dados Consolidados'!$H$2:$H$38, 0))) -> #N/A | AC27: =INT(INDEX('Dados Consolidados'!$V$2:$V$38, MATCH(J27, 'Dados Consolidados'!$J$2:$J$38, 0))) -> #N/A | AD27: =INT(INDEX('Dados Consolidados'!$W$2:$W$38, MATCH(P27, 'Dados Consolidados'!$P$2:$P$38, 0))) -> #N/A
Y28: =INT(INDEX('Dados Consolidados'!$R$2:$R$38, MATCH(A28, 'Dados Consolidados'!$A$2:$A$38, 0))) -> #N/A | Z28: =INT(INDEX('Dados Consolidados'!$S$2:$S$38, MATCH(B28, 'Dados Consolidados'!$B$2:$B$38, 0))) -> #N/A | AA28: =INT(INDEX('Dados Consolidados'!$T$2:$T$38, MATCH(E28, 'Dados Consolidados'!$E$2:$E$38, 0))) -> #N/A | AB28: =INT(INDEX('Dados Consolidados'!$U$2:$U$38, MATCH(H28, 'Dados Consolidados'!$H$2:$H$38, 0))) -> #N/A | AC28: =INT(INDEX('Dados Consolidados'!$V$2:$V$38, MATCH(J28, 'Dados Consolidados'!$J$2:$J$38, 0))) -> #N/A | AD28: =INT(INDEX('Dados Consolidados'!$W$2:$W$38, MATCH(P28, 'Dados Consolidados'!$P$2:$P$38, 0))) -> #N/A
... Y200: =INT(INDEX('Dados Consolidados'!$R$2:$R$38, MATCH(A200, 'Dados Consolidados'!$A$2:$A$38, 0))) -> #N/A | Z200: =INT(INDEX('Dados Consolidados'!$S$2:$S$38, MATCH(B200, 'Dados Consolidados'!$B$2:$B$38, 0))) -> #N/A | AA200: =INT(INDEX('Dados Consolidados'!$T$2:$T$38, MATCH(E200, 'Dados Consolidados'!$E$2:$E$38, 0))) -> #N/A | AB200: =INT(INDEX('Dados Consolidados'!$U$2:$U$38, MATCH(H200, 'Dados Consolidados'!$H$2:$H$38, 0))) -> #N/A | AC200: =INT(INDEX('Dados Consolidados'!$V$2:$V$38, MATCH(J200, 'Dados Consolidados'!$J$2:$J$38, 0))) -> #N/A | AD200: =INT(INDEX('Dados Consolidados'!$W$2:$W$38, MATCH(P200, 'Dados Consolidados'!$P$2:$P$38, 0))) -> #N/A

Sheet Cadastro de Pedidos
A1: Seção

Sheet Cadastro de Marcas
A1: Cadastros Básicos > Marca
A2: Cadastro de Marcas
A3: Nome
A4: Obrigatório
A5: Máximo 50 caracteres.

Sheet Dados Consolidados
A2: 1 - BEBE | B2: 1 - MACACAO | E2: 1 - ABRANGE | H2: 3 - SUELI IVANOW | J2: 1 - PC | P2: 5 - Remarcacao Zebra | R2: 1 | S2: 1 | T2: 1 | U2: 3 | V2: 1 | W2: 5
A3: 2 - BOLSA CINTO ACESS | B3: 2 - BERCO | E3: 2 - ACILIO BREDA | H3: 4 - LUCIA MARIANO | J3: 2 - METRO | P3: 10 - ETIQUETA DESENV | R3: 2 | S3: 2 | T3: 2 | U3: 4 | V3: 2 | W3: 10
A4: 3 - BRINQUEDO | B4: 3 - ENXOVAL | E4: 3 - ACOFF | H4: 5 - NATALIA CAROLINE | J4: 3 - PAR | P4: 14 - ETIQUETA ADESIVA CODIGO NEXTT ZEBRA | R4: 3 | S4: 3 | T4: 3 | U4: 5 | V4: 3 | W4: 14
A5: 4 - CAMA MESA BANHO | B5: 4 - HIGIENE | E5: 4 - ADG CONFECCOES | H5: 6 - ERIK WALLISON | J5: 4 - 1 | P5: 16 - ETIQUETA ADESIVA 2 CODIGO NEXTT ZEBRA | R5: 4 | S5: 4 | T5: 4 | U5: 6 | V5: 4 | W5: 16
A6: 5 - CARRINHO BEBE ACESS | B6: 5 - ACESSORIO | E6: 5 - ADK | H6: 9 - HELOISA FERNANDES PEREIRA | J6: 5 - N | P6: 17 - Etiqueta Adesiva GC420t | R6: 5 | S6: 5 | T6: 5 | U6: 9 | V6: 5 | W6: 17
A7: 6 - CARTAO PRESENTE | B7: 1 - BIJOUTERIA | E7: 6 - AGANESTAR | H7: 10 - LAIS GONCALVES OLIVEIRA | J7: 6 - PE A | P7: 18 - ETIQUETA VOLUME TRANSFERÊNCIA | R7: 6 | S7: 6 | T7: 6 | U7: 10 | V7: 6 | W7: 18
A8: 7 - ELETROELETRONICO | B8: 2 - SOMBRINHA GUARDA CHUV | E8: 7 - AHVAZ | H8: 12 - ANDREIA DE ARAUJO VALENTE | J8: 7 - U | P8: 19 - ETIQUETA PADRÃO PACK DE PRODUTOS | R8: 7 | S8: 7 | T8: 7 | U8: 12 | V8: 7 | W8: 19
A9: 8 - ELETROPORTATEIS | B9: 3 - ACESSORIO FEMININO | E9: 8 - AISTHY | H9: 13 - ANGELICA RAIANE | J9: 8 - UM | P9: 20 - Etiqueta SKINA TAG 2 COL - TLP2844 | R9: 8 | S9: 8 | T9: 8 | U9: 13 | V9: 8 | W9: 20
A10: 9 - EVENTUAIS | B10: 4 - BOLSA | E10: 9 - AKIYOSHI | H10: 14 - FRANCIELE CRISTINA SANTOS DE GODOY | J10: 9 - UN | P10: 21 - ETQ - SKINA 34X23 - TLP2844 | R10: 9 | S10: 9 | T10: 9 | U10: 14 | V10: 9 | W10: 21
A11: 10 - FEMININO CLASSICO | B11: 1 - BONECA | E11: 10 - ANDREZA | H11: 16 - SUZIANI ALVES FERNANDES | P11: 22 - Etq - Remarcacao - SKINA - TLP2844 | R11: 10 | S11: 10 | T11: 10 | U11: 16 | W11: 22
A12: 11 - FEMININO CONTEMPORANEO | B12: 2 - DIVERSOS | E12: 11 - ANDRIMALHAS | H12: 17 - CAROLINE TEIXEIRA DA SILVA | P12: 23 - Etiqueta SKINA TAG 2 COL - GC420T | R12: 11 | T12: 11 | U12: 17 | W12: 23
A13: 12 - FEMININO JOVEM | B13: 3 - PELUCIA | E13: 12 - ANGERO MALHAS | H13: 18 - CLAUDIA LEMES PEREIRA | R13: 12 | T13: 12 | U13: 18
A14: 13 - GINASTICA FEMININA | B14: 4 - CHAO | E14: 13 - ANT SHOK | H14: 19 - VENDEDOR LOJA 01 | R14: 13 | T14: 13 | U14: 19
A15: 14 - INFANTIL MENINA | B15: 5 - ELETRONICO | E15: 15 - AQUARELA ME | H15: 20 - VENDEDOR LOJA 02 | R15: 14 | T15: 15 | U15: 20
A16: 15 - INFANTIL MENINO | B16: 1 - CAMA | E16: 16 - ATUAL | H16: 21 - IVANI PEREZ RUIVO | R16: 15 | T16: 16 | U16: 21
A17: 16 - INVERNO FEM CONT CLASS | B17: 2 - BANHO | E17: 17 - AVAL TEXTIL FARAELI | H17: 22 - PRISCILA FERNANDES | R17: 16 | T17: 17 | U17: 22
A18: 17 - INVERNO FEMININO JOVEM | B18: 3 - MESA | E18: 18 - AYONA | H18: 24 - HELEN CHOBBA | R18: 17 | T18: 18 | U18: 24
A19: 18 - JEANS FEMININO JOVEM | B19: 1 - CARRINHO | E19: 20 - BACCI | H19: 27 - ALISON SILVA | R19: 18 | T19: 20 | U19: 27
A20: 19 - JEANS FEMININO TG | B20: 2 - ANDADOR | E20: 21 - BANDEIRANTE | H20: 30 - ROSILENE ALVES LINS | R20: 19 | T20: 21 | U20: 30
A21: 20 - JEANS MASCULINO | B21: 3 - CADEIRA | E21: 22 - BDB FERRAMENTAS | H21: 34 - CONTABILIDADE | R21: 20 | T21: 22 | U21: 34
A22: 21 - JUVENIL MENINA | B22: 1 - CARTAO PRESENTE | E22: 23 - BEACH E COUNTRY | H22: 35 - ELIETE | R22: 21 | T22: 23 | U22: 35
A23: 22 - JUVENIL MENINO | B23: 1 - RADIO | E23: 24 - BELLOT | H23: 37 - CLAUDINEY OLIVEIRA | R23: 22 | T23: 24 | U23: 37
A24: 23 - LINGERIE | B24: 2 - TELEFONE | E24: 25 - BESTIE | H24: 38 - ANDREIA DE ARAUJO VALENTE | R24: 23 | T24: 25 | U24: 38
... A32: 31 - PRIM PASSOS MENINA | B32: 3 - BLUSA TOP CAMISETA | E32: 38 - BRANDILI | H32: 54 - ANA CRISTINA ALVES | R32: 31 | T32: 38 | U32: 54
A33: 32 - PRIM PASSOS MENINO | B33: 4 - SHORTS BERMUDA | E33: 39 - BRASCOL | R33: 32 | T33: 39 | U33: 7
A34: 33 - PRODUTOS DIVERSOS | B34: 5 - VESTIDO MACACAO | E34: 40 - BRASKIT | R34: 33 | T34: 40 | U34: 11
A35: 34 - TEEN FEMININO | B35: 6 - SOBREPOSICAO | E35: 41 - BRILHANTE | R35: 34 | T35: 41 | U35: 15
A36: 35 - TEEN MASCULINO | B36: 7 - CONJUNTO | E36: 42 - BRILHO TEEN | R36: 35 | T36: 42 | U36: 23
A37: 36 - UTILID PARA O LAR | B37: 8 - BLUSA M L | E37: 43 - BROOKS | R37: 36 | T37: 43 | U37: 25
A38: 37 - CALÇADOS | B38: 1 - SAIA | E38: 44 - BUBA | R38: 37 | T38: 44 | U38: 26
B39: 2 - CALCA | E39: 45 - BUDDEMEYER | T39: 45 | U39: 28
B40: 3 - BLUSA TOP CAMISETA | E40: 46 - CADENCE | T40: 46 | U40: 29
B41: 4 - SHORTS BERMUDA | E41: 47 - CAEDU | T41: 47 | U41: 31
B42: 5 - VESTIDO MACACAO | E42: 48 - CALESITA | T42: 48 | U42: 32
B43: 6 - SOBREPOSICAO | E43: 49 - CAMELO | T43: 49 | U43: 33
B44: 7 - BLUSA M L | E44: 50 - CAMESA | T44: 50 | U44: 36
B45: 1 - CALCA | E45: 52 - CAMPCENTER | T45: 52 | U45: 40
B46: 2 - BLUSA TOP CAMISETA | E46: 53 - CANDIDE | T46: 53 | U46: 41
B47: 3 - SOBREPOSICAO | E47: 54 - CAROLINA CONFECCOES | T47: 54 | U47: 49
B48: 4 - VESTIDO MACACAO | E48: 55 - CENSATO | T48: 55 | U48: 50
...
