Workbook
Name Seção1: 'Dados Consolidados'!$S$2:$S$6
Name Seção1: 'Dados Consolidados'!$S$2:$S$6
Name Seção10: 'Dados Consolidados'!$S$30:$S$37
Name Seção11: 'Dados Consolidados'!$S$38:$S$44
Name Seção12: 'Dados Consolidados'!$S$45:$S$51
Name Seção13: 'Dados Consolidados'!$S$52:$S$55
Name Seção14: 'Dados Consolidados'!$S$56:$S$65
Name Seção15: 'Dados Consolidados'!$S$66:$S$74
Name Seção16: 'Dados Consolidados'!$S$75
Name Seção17: 'Dados Consolidados'!$S$76
Name Seção18: 'Dados Consolidados'!$S$77:$S$83
Name Seção19: 'Dados Consolidados'!$S$84:$S$90
Name Seção2: 'Dados Consolidados'!$S$7:$S$10
Name Seção2: 'Dados Consolidados'!$S$7:$S$10
Name Seção20: 'Dados Consolidados'!$S$91:$S$98
Name Seção21: 'Dados Consolidados'!$S$99:$S$108
Name Seção22: 'Dados Consolidados'!$S$109:$S$117
Name Seção23: 'Dados Consolidados'!$S$118:$S$122
Name Seção24: 'Dados Consolidados'!$S$123:$S$128
Name Seção25: 'Dados Consolidados'!$S$129:$S$131
Name Seção26: 'Dados Consolidados'!$S$132:$S$135
Name Seção27: 'Dados Consolidados'!$S$136:$S$140
Name Seção28: 'Dados Consolidados'!$S$141:$S$145
Name Seção29: 'Dados Consolidados'!$S$146:$S$154
Name Seção3: 'Dados Consolidados'!$S$11:$S$15
Name Seção30: 'Dados Consolidados'!$S$155:$S$159
Name Seção31: 'Dados Consolidados'!$S$160:$S$168
Name Seção32: 'Dados Consolidados'!$S$169:$S$177
Name Seção33: 'Dados Consolidados'!$S$178
Name Seção34: 'Dados Consolidados'!$S$179:$S$185
Name Seção35: 'Dados Consolidados'!$S$186:$S$193
Name Seção36: 'Dados Consolidados'!$S$194:$S$196
Name Seção4: 'Dados Consolidados'!$S$16:$S$18
Name Seção5: 'Dados Consolidados'!$S$19:$S$21
Name Seção6: 'Dados Consolidados'!$S$22
Name Seção7: 'Dados Consolidados'!$S$23:$S$24
Name Seção8: 'Dados Consolidados'!$S$25:$S$27
Name Seção9: 'Dados Consolidados'!$S$28:$S$29
Name SeçãoCompleta1: 'Dados Consolidados'!$B$2:$B$6
Name SeçãoCompleta10: 'Dados Consolidados'!$B$30:$B$37
Name SeçãoCompleta11: 'Dados Consolidados'!$B$38:$B$44
Name SeçãoCompleta12: 'Dados Consolidados'!$B$45:$B$51
Name SeçãoCompleta13: 'Dados Consolidados'!$B$52:$B$55
Name SeçãoCompleta14: 'Dados Consolidados'!$B$56:$B$65
Name SeçãoCompleta15: 'Dados Consolidados'!$B$66:$B$74
Name SeçãoCompleta16: 'Dados Consolidados'!$B$75
Name SeçãoCompleta17: 'Dados Consolidados'!$B$76
Name SeçãoCompleta18: 'Dados Consolidados'!$B$77:$B$83
Name SeçãoCompleta19: 'Dados Consolidados'!$B$84:$B$90
Name SeçãoCompleta2: 'Dados Consolidados'!$B$7:$B$10
Name SeçãoCompleta20: 'Dados Consolidados'!$B$91:$B$98
Name SeçãoCompleta21: 'Dados Consolidados'!$B$99:$B$108
Name SeçãoCompleta22: 'Dados Consolidados'!$B$109:$B$117
Name SeçãoCompleta23: 'Dados Consolidados'!$B$118:$B$122
Name SeçãoCompleta24: 'Dados Consolidados'!$B$123:$B$128
Name SeçãoCompleta25: 'Dados Consolidados'!$B$129:$B$131
Name SeçãoCompleta26: 'Dados Consolidados'!$B$132:$B$135
Name SeçãoCompleta27: 'Dados Consolidados'!$B$136:$B$140
Name SeçãoCompleta28: 'Dados Consolidados'!$B$141:$B$145
Name SeçãoCompleta29: 'Dados Consolidados'!$B$146:$B$154

Sheet Nextt
D2: Cadastre vários itens simultaneamente
D3: Preencha os dados do que quiser cadastrar.
B7: Categorias: | G7: Envie a planilha Excel
B9: Cadastro de Produtos
B10: Cadastro de Pedidos | H10: Ao terminar, lembre-se de salvar e importar a planilha Excel para o Matriz
B11: Cadastro de Marcas

Sheet Cadastro de Produtos
A1: Cadastros Básicos > Produto | Q1: Atributos | Y1: Banco de Dados
A2: Cadastro de Produtos Skina
A3: Seção | B3: Espécie | C3: Descrição | D3: Descrição Reduzida | E3: Marca | F3: Referência do Fornecedor | G3: Código Original | H3: Comprador | I3: Produto Ativo? | J3: Unidade | K3: Classificação Fiscal | L3: Origem | M3: Valor de Venda | N3: % ICMS | O3: % IPI | P3: Etiqueta Padrão | Y3: Seção | Z3: Espécie | AA3: Marca | AB3: Comprador | AC3: Unidade | AD3: Classificacao Fiscal | AE3: Etiqueta Padrão
A4: Obrigatório | B4: Obrigatório | C4: Obrigatório | D4: Obrigatório | E4: Obrigatório | F4: Obrigatório | H4: Obrigatório | J4: Obrigatório | K4: Obrigatório | L4: Obrigatório | M4: Obrigatório | P4: Obrigatório | Y4: Os valores abaixo servem para consolidar os dados selecionados nos menus suspensos das tabelas acima e garantir uma integração eficiente com o banco de dados. Por esse motivo, essas células estão protegidas.
A5: Aviso: Os valores disponíveis para "seção" são importados automaticamente do banco de dados do Matriz. | B5: Aviso: Os valores disponíveis para "espécie" são importados automaticamente do banco de dados do Matriz. | C5: Máximo 50 caracteres. Dica: Se a sua descrição incluir os mesmos valores de "seção" e/ou "espécie", remova as palavras repetidas para evitar duplicidade na impressão da etiqueta. | D5: Máximo 50 caracteres. Dica: A "descrição reduzida" geralmente inclui apenas uma ou duas palavras-chave relacionadas à "descrição". | E5: Aviso: Os valores disponíveis para "marca" são importados automaticamente do banco de dados do Matriz. | H5: Aviso: Os valores disponíveis para "comprador" são importados automaticamente do banco de dados do Matriz. | I5: Por padrão, os valores de "Produto Ativo?" são definidos como 1. | J5: Aviso: Os valores disponíveis para "unidade" são importados automaticamente do banco de dados do Matriz. | K5: Aviso: Os valores disponíveis para "classificação fiscal" são importados automaticamente do banco de dados do Matriz. | P5: Aviso: Os valores disponíveis para "etiqueta padrão" são importados automaticamente do banco de dados do Matriz.
E6: Para cadastro de 'Marca' em lotes, clique aqui
A7: 3 - BRINQUEDO | B7: 5 - ELETRONICO | C7: Descrição Teste 1 | D7: Descrição Reduzida Teste 1 | E7: 2 - ACILIO BREDA | F7: ref1 | H7: 5 - NATALIA CAROLINE | I7: 1 | J7: 1 - PC | K7: 84669311 - Para máquinas da subposição 8456.20 | L7: 0 | M7: 77536 | N7: 0 | O7: 0 | P7: 5 - Remarcacao Zebra | Y7: =INT(INDEX('Dados Consolidados'!$R$2:$R$1000000, MATCH(A7, 'Dados Consolidados'!$A$2:$A$1000000, 0))) -> 3 | Z7: =INT(INDEX('Dados Consolidados'!$S$2:$S$1000000, MATCH(B7, 'Dados Consolidados'!$B$2:$B$1000000, 0))) -> 5 | AA7: =INT(INDEX('Dados Consolidados'!$T$2:$T$1000000, MATCH(E7, 'Dados Consolidados'!$E$2:$E$1000000, 0))) -> 2 | AB7: =INT(INDEX('Dados Consolidados'!$U$2:$U$1000000, MATCH(H7, 'Dados Consolidados'!$H$2:$H$1000000, 0))) -> 5 | AC7: =INT(INDEX('Dados Consolidados'!$V$2:$V$1000000, MATCH(J7, 'Dados Consolidados'!$J$2:$J$1000000, 0))) -> 1 | AD7: =INT(INDEX('Dados Consolidados'!$X$2:$X$1000000, MATCH(K7, 'Dados Consolidados'!$K$2:$K$1000000, 0))) -> 30299 | AE7: =INT(INDEX('Dados Consolidados'!$W$2:$W$1000000, MATCH(P7, 'Dados Consolidados'!$P$2:$P$1000000, 0))) -> 5
Y8: =INT(INDEX('Dados Consolidados'!$R$2:$R$1000000, MATCH(A8, 'Dados Consolidados'!$A$2:$A$1000000, 0))) -> #N/A | Z8: =INT(INDEX('Dados Consolidados'!$S$2:$S$1000000, MATCH(B8, 'Dados Consolidados'!$B$2:$B$1000000, 0))) -> #N/A | AA8: =INT(INDEX('Dados Consolidados'!$T$2:$T$1000000, MATCH(E8, 'Dados Consolidados'!$E$2:$E$1000000, 0))) -> #N/A | AB8: =INT(INDEX('Dados Consolidados'!$U$2:$U$1000000, MATCH(H8, 'Dados Consolidados'!$H$2:$H$1000000, 0))) -> #N/A | AC8: =INT(INDEX('Dados Consolidados'!$V$2:$V$1000000, MATCH(J8, 'Dados Consolidados'!$J$2:$J$1000000, 0))) -> #N/A | AD8: =INT(INDEX('Dados Consolidados'!$X$2:$X$1000000, MATCH(K8, 'Dados Consolidados'!$K$2:$K$1000000, 0))) -> #N/A | AE8: =INT(INDEX('Dados Consolidados'!$W$2:$W$1000000, MATCH(P8, 'Dados Consolidados'!$P$2:$P$1000000, 0))) -> #N/A
A9: 21 - JUVENIL MENINA | B9: 9 - SOBREPOSICAO | Y9: =INT(INDEX('Dados Consolidados'!$R$2:$R$1000000, MATCH(A9, 'Dados Consolidados'!$A$2:$A$1000000, 0))) -> 21 | Z9: =INT(INDEX('Dados Consolidados'!$S$2:$S$1000000, MATCH(B9, 'Dados Consolidados'!$B$2:$B$1000000, 0))) -> 9 | AA9: =INT(INDEX('Dados Consolidados'!$T$2:$T$1000000, MATCH(E9, 'Dados Consolidados'!$E$2:$E$1000000, 0))) -> #N/A | AB9: =INT(INDEX('Dados Consolidados'!$U$2:$U$1000000, MATCH(H9, 'Dados Consolidados'!$H$2:$H$1000000, 0))) -> #N/A | AC9: =INT(INDEX('Dados Consolidados'!$V$2:$V$1000000, MATCH(J9, 'Dados Consolidados'!$J$2:$J$1000000, 0))) -> #N/A | AD9: =INT(INDEX('Dados Consolidados'!$X$2:$X$1000000, MATCH(K9, 'Dados Consolidados'!$K$2:$K$1000000, 0))) -> #N/A | AE9: =INT(INDEX('Dados Consolidados'!$W$2:$W$1000000, MATCH(P9, 'Dados Consolidados'!$P$2:$P$1000000, 0))) -> #N/A
Y10: =INT(INDEX('Dados Consolidados'!$R$2:$R$1000000, MATCH(A10, 'Dados Consolidados'!$A$2:$A$1000000, 0))) -> #N/A | Z10: =INT(INDEX('Dados Consolidados'!$S$2:$S$1000000, MATCH(B10, 'Dados Consolidados'!$B$2:$B$1000000, 0))) -> #N/A | AA10: =INT(INDEX('Dados Consolidados'!$T$2:$T$1000000, MATCH(E10, 'Dados Consolidados'!$E$2:$E$1000000, 0))) -> #N/A | AB10: =INT(INDEX('Dados Consolidados'!$U$2:$U$1000000, MATCH(H10, 'Dados Consolidados'!$H$2:$H$1000000, 0))) -> #N/A | AC10: =INT(INDEX('Dados Consolidados'!$V$2:$V$1000000, MATCH(J10, 'Dados Consolidados'!$J$2:$J$1000000, 0))) -> #N/A | AD10: =INT(INDEX('Dados Consolidados'!$X$2:$X$1000000, MATCH(K10, 'Dados Consolidados'!$K$2:$K$1000000, 0))) -> #N/A | AE10: =INT(INDEX('Dados Consolidados'!$W$2:$W$1000000, MATCH(P10, 'Dados Consolidados'!$P$2:$P$1000000, 0))) -> #N/A
Y11: =INT(INDEX('Dados Consolidados'!$R$2:$R$1000000, MATCH(A11, 'Dados Consolidados'!$A$2:$A$1000000, 0))) -> #N/A | Z11: =INT(INDEX('Dados Consolidados'!$S$2:$S$1000000, MATCH(B11, 'Dados Consolidados'!$B$2:$B$1000000, 0))) -> #N/A | AA11: =INT(INDEX('Dados Consolidados'!$T$2:$T$1000000, MATCH(E11, 'Dados Consolidados'!$E$2:$E$1000000, 0))) -> #N/A | AB11: =INT(INDEX('Dados Consolidados'!$U$2:$U$1000000, MATCH(H11, 'Dados Consolidados'!$H$2:$H$1000000, 0))) -> #N/A | AC11: =INT(INDEX('Dados Consolidados'!$V$2:$V$1000000, MATCH(J11, 'Dados Consolidados'!$J$2:$J$1000000, 0))) -> #N/A | AD11: =INT(INDEX('Dados Consolidados'!$X$2:$X$1000000, MATCH(K11, 'Dados Consolidados'!$K$2:$K$1000000, 0))) -> #N/A | AE11: =INT(INDEX('Dados Consolidados'!$W$2:$W$1000000, MATCH(P11, 'Dados Consolidados'!$P$2:$P$1000000, 0))) -> #N/A
Y12: =INT(INDEX('Dados Consolidados'!$R$2:$R$1000000, MATCH(A12, 'Dados Consolidados'!$A$2:$A$1000000, 0))) -> #N/A | Z12: =INT(INDEX('Dados Consolidados'!$S$2:$S$1000000, MATCH(B12, 'Dados Consolidados'!$B$2:$B$1000000, 0))) -> #N/A | AA12: =INT(INDEX('Dados Consolidados'!$T$2:$T$1000000, MATCH(E12, 'Dados Consolidados'!$E$2:$E$1000000, 0))) -> #N/A | AB12: =INT(INDEX('Dados Consolidados'!$U$2:$U$1000000, MATCH(H12, 'Dados Consolidados'!$H$2:$H$1000000, 0))) -> #N/A | AC12: =INT(INDEX('Dados Consolidados'!$V$2:$V$1000000, MATCH(J12, 'Dados Consolidados'!$J$2:$J$1000000, 0))) -> #N/A | AD12: =INT(INDEX('Dados Consolidados'!$X$2:$X$1000000, MATCH(K12, 'Dados Consolidados'!$K$2:$K$1000000, 0))) -> #N/A | AE12: =INT(INDEX('Dados Consolidados'!$W$2:$W$1000000, MATCH(P12, 'Dados Consolidados'!$P$2:$P$1000000, 0))) -> #N/A
Y13: =INT(INDEX('Dados Consolidados'!$R$2:$R$1000000, MATCH(A13, 'Dados Consolidados'!$A$2:$A$1000000, 0))) -> #N/A | Z13: =INT(INDEX('Dados Consolidados'!$S$2:$S$1000000, MATCH(B13, 'Dados Consolidados'!$B$2:$B$1000000, 0))) -> #N/A | AA13: =INT(INDEX('Dados Consolidados'!$T$2:$T$1000000, MATCH(E13, 'Dados Consolidados'!$E$2:$E$1000000, 0))) -> #N/A | AB13: =INT(INDEX('Dados Consolidados'!$U$2:$U$1000000, MATCH(H13, 'Dados Consolidados'!$H$2:$H$1000000, 0))) -> #N/A | AC13: =INT(INDEX('Dados Consolidados'!$V$2:$V$1000000, MATCH(J13, 'Dados Consolidados'!$J$2:$J$1000000, 0))) -> #N/A | AD13: =INT(INDEX('Dados Consolidados'!$X$2:$X$1000000, MATCH(K13, 'Dados Consolidados'!$K$2:$K$1000000, 0))) -> #N/A | AE13: =INT(INDEX('Dados Consolidados'!$W$2:$W$1000000, MATCH(P13, 'Dados Consolidados'!$P$2:$P$1000000, 0))) -> #N/A
Y14: =INT(INDEX('Dados Consolidados'!$R$2:$R$1000000, MATCH(A14, 'Dados Consolidados'!$A$2:$A$1000000, 0))) -> #N/A | Z14: =INT(INDEX('Dados Consolidados'!$S$2:$S$1000000, MATCH(B14, 'Dados Consolidados'!$B$2:$B$1000000, 0))) -> #N/A | AA14: =INT(INDEX('Dados Consolidados'!$T$2:$T$1000000, MATCH(E14, 'Dados Consolidados'!$E$2:$E$1000000, 0))) -> #N/A | AB14: =INT(INDEX('Dados Consolidados'!$U$2:$U$1000000, MATCH(H14, 'Dados Consolidados'!$H$2:$H$1000000, 0))) -> #N/A | AC14: =INT(INDEX('Dados Consolidados'!$V$2:$V$1000000, MATCH(J14, 'Dados Consolidados'!$J$2:$J$1000000, 0))) -> #N/A | AD14: =INT(INDEX('Dados Consolidados'!$X$2:$X$1000000, MATCH(K14, 'Dados Consolidados'!$K$2:$K$1000000, 0))) -> #N/A | AE14: =INT(INDEX('Dados Consolidados'!$W$2:$W$1000000, MATCH(P14, 'Dados Consolidados'!$P$2:$P$1000000, 0))) -> #N/A
Y15: =INT(INDEX('Dados Consolidados'!$R$2:$R$1000000, MATCH(A15, 'Dados Consolidados'!$A$2:$A$1000000, 0))) -> #N/A | Z15: =INT(INDEX('Dados Consolidados'!$S$2:$S$1000000, MATCH(B15, 'Dados Consolidados'!$B$2:$B$1000000, 0))) -> #N/A | AA15: =INT(INDEX('Dados Consolidados'!$T$2:$T$1000000, MATCH(E15, 'Dados Consolidados'!$E$2:$E$1000000, 0))) -> #N/A | AB15: =INT(INDEX('Dados Consolidados'!$U$2:$U$1000000, MATCH(H15, 'Dados Consolidados'!$H$2:$H$1000000, 0))) -> #N/A | AC15: =INT(INDEX('Dados Consolidados'!$V$2:$V$1000000, MATCH(J15, 'Dados Consolidados'!$J$2:$J$1000000, 0))) -> #N/A | AD15: =INT(INDEX('Dados Consolidados'!$X$2:$X$1000000, MATCH(K15, 'Dados Consolidados'!$K$2:$K$1000000, 0))) -> #N/A | AE15: =INT(INDEX('Dados Consolidados'!$W$2:$W$1000000, MATCH(P15, 'Dados Consolidados'!$P$2:$P$1000000, 0))) -> #N/A
Y16: =INT(INDEX('Dados Consolidados'!$R$2:$R$1000000, MATCH(A16, 'Dados Consolidados'!$A$2:$A$1000000, 0))) -> #N/A | Z16: =INT(INDEX('Dados Consolidados'!$S$2:$S$1000000, MATCH(B16, 'Dados Consolidados'!$B$2:$B$1000000, 0))) -> #N/A | AA16: =INT(INDEX('Dados Consolidados'!$T$2:$T$1000000, MATCH(E16, 'Dados Consolidados'!$E$2:$E$1000000, 0))) -> #N/A | AB16: =INT(INDEX('Dados Consolidados'!$U$2:$U$1000000, MATCH(H16, 'Dados Consolidados'!$H$2:$H$1000000, 0))) -> #N/A | AC16: =INT(INDEX('Dados Consolidados'!$V$2:$V$1000000, MATCH(J16, 'Dados Consolidados'!$J$2:$J$1000000, 0))) -> #N/A | AD16: =INT(INDEX('Dados Consolidados'!$X$2:$X$1000000, MATCH(K16, 'Dados Consolidados'!$K$2:$K$1000000, 0))) -> #N/A | AE16: =INT(INDEX('Dados Consolidados'!$W$2:$W$1000000, MATCH(P16, 'Dados Consolidados'!$P$2:$P$1000000, 0))) -> #N/A
Y17: =INT(INDEX('Dados Consolidados'!$R$2:$R$1000000, MATCH(A17, 'Dados Consolidados'!$A$2:$A$1000000, 0))) -> #N/A | Z17: =INT(INDEX('Dados Consolidados'!$S$2:$S$1000000, MATCH(B17, 'Dados Consolidados'!$B$2:$B$1000000, 0))) -> #N/A | AA17: =INT(INDEX('Dados Consolidados'!$T$2:$T$1000000, MATCH(E17, 'Dados Consolidados'!$E$2:$E$1000000, 0))) -> #N/A | AB17: =INT(INDEX('Dados Consolidados'!$U$2:$U$1000000, MATCH(H17, 'Dados Consolidados'!$H$2:$H$1000000, 0))) -> #N/A | AC17: =INT(INDEX('Dados Consolidados'!$V$2:$V$1000000, MATCH(J17, 'Dados Consolidados'!$J$2:$J$1000000, 0))) -> #N/A | AD17: =INT(INDEX('Dados Consolidados'!$X$2:$X$1000000, MATCH(K17, 'Dados Consolidados'!$K$2:$K$1000000, 0))) -> #N/A | AE17: =INT(INDEX('Dados Consolidados'!$W$2:$W$1000000, MATCH(P17, 'Dados Consolidados'!$P$2:$P$1000000, 0))) -> #N/A
Y18: =INT(INDEX('Dados Consolidados'!$R$2:$R$1000000, MATCH(A18, 'Dados Consolidados'!$A$2:$A$1000000, 0))) -> #N/A | Z18: =INT(INDEX('Dados Consolidados'!$S$2:$S$1000000, MATCH(B18, 'Dados Consolidados'!$B$2:$B$1000000, 0))) -> #N/A | AA18: =INT(INDEX('Dados Consolidados'!$T$2:$T$1000000, MATCH(E18, 'Dados Consolidados'!$E$2:$E$1000000, 0))) -> #N/A | AB18: =INT(INDEX('Dados Consolidados'!$U$2:$U$1000000, MATCH(H18, 'Dados Consolidados'!$H$2:$H$1000000, 0))) -> #N/A | AC18: =INT(INDEX('Dados Consolidados'!$V$2:$V$1000000, MATCH(J18, 'Dados Consolidados'!$J$2:$J$1000000, 0))) -> #N/A | AD18: =INT(INDEX('Dados Consolidados'!$X$2:$X$1000000, MATCH(K18, 'Dados Consolidados'!$K$2:$K$1000000, 0))) -> #N/A | AE18: =INT(INDEX('Dados Consolidados'!$W$2:$W$1000000, MATCH(P18, 'Dados Consolidados'!$P$2:$P$1000000, 0))) -> #N/A
Y19: =INT(INDEX('Dados Consolidados'!$R$2:$R$1000000, MATCH(A19, 'Dados Consolidados'!$A$2:$A$1000000, 0))) -> #N/A | Z19: =INT(INDEX('Dados Consolidados'!$S$2:$S$1000000, MATCH(B19, 'Dados Consolidados'!$B$2:$B$1000000, 0))) -> #N/A | AA19: =INT(INDEX('Dados Consolidados'!$T$2:$T$1000000, MATCH(E19, 'Dados Consolidados'!$E$2:$E$1000000, 0))) -> #N/A | AB19: =INT(INDEX('Dados Consolidados'!$U$2:$U$1000000, MATCH(H19, 'Dados Consolidados'!$H$2:$H$1000000, 0))) -> #N/A | AC19: =INT(INDEX('Dados Consolidados'!$V$2:$V$1000000, MATCH(J19, 'Dados Consolidados'!$J$2:$J$1000000, 0))) -> #N/A | AD19: =INT(INDEX('Dados Consolidados'!$X$2:$X$1000000, MATCH(K19, 'Dados Consolidados'!$K$2:$K$1000000, 0))) -> #N/A | AE19: =INT(INDEX('Dados Consolidados'!$W$2:$W$1000000, MATCH(P19, 'Dados Consolidados'!$P$2:$P$1000000, 0))) -> #N/A
Y20: =INT(INDEX('Dados Consolidados'!$R$2:$R$1000000, MATCH(A20, 'Dados Consolidados'!$A$2:$A$1000000, 0))) -> #N/A | Z20: =INT(INDEX('Dados Consolidados'!$S$2:$S$1000000, MATCH(B20, 'Dados Consolidados'!$B$2:$B$1000000, 0))) -> #N/A | AA20: =INT(INDEX('Dados Consolidados'!$T$2:$T$1000000, MATCH(E20, 'Dados Consolidados'!$E$2:$E$1000000, 0))) -> #N/A | AB20: =INT(INDEX('Dados Consolidados'!$U$2:$U$1000000, MATCH(H20, 'Dados Consolidados'!$H$2:$H$1000000, 0))) -> #N/A | AC20: =INT(INDEX('Dados Consolidados'!$V$2:$V$1000000, MATCH(J20, 'Dados Consolidados'!$J$2:$J$1000000, 0))) -> #N/A | AD20: =INT(INDEX('Dados Consolidados'!$X$2:$X$1000000, MATCH(K20, 'Dados Consolidados'!$K$2:$K$1000000, 0))) -> #N/A | AE20: =INT(INDEX('Dados Consolidados'!$W$2:$W$1000000, MATCH(P20, 'Dados Consolidados'!$P$2:$P$1000000, 0))) -> #N/A
Y21: =INT(INDEX('Dados Consolidados'!$R$2:$R$1000000, MATCH(A21, 'Dados Consolidados'!$A$2:$A$1000000, 0))) -> #N/A | Z21: =INT(INDEX('Dados Consolidados'!$S$2:$S$1000000, MATCH(B21, 'Dados Consolidados'!$B$2:$B$1000000, 0))) -> #N/A | AA21: =INT(INDEX('Dados Consolidados'!$T$2:$T$1000000, MATCH(E21, 'Dados Consolidados'!$E$2:$E$1000000, 0))) -> #N/A | AB21: =INT(INDEX('Dados Consolidados'!$U$2:$U$1000000, MATCH(H21, 'Dados Consolidados'!$H$2:$H$1000000, 0))) -> #N/A | AC21: =INT(INDEX('Dados Consolidados'!$V$2:$V$1000000, MATCH(J21, 'Dados Consolidados'!$J$2:$J$1000000, 0))) -> #N/A | AD21: =INT(INDEX('Dados Consolidados'!$X$2:$X$1000000, MATCH(K21, 'Dados Consolidados'!$K$2:$K$1000000, 0))) -> #N/A | AE21: =INT(INDEX('Dados Consolidados'!$W$2:$W$1000000, MATCH(P21, 'Dados Consolidados'!$P$2:$P$1000000, 0))) -> #N/A
... Y201: =INT(INDEX('Dados Consolidados'!$R$2:$R$1000000, MATCH(A201, 'Dados Consolidados'!$A$2:$A$1000000, 0))) -> #N/A | Z201: =INT(INDEX('Dados Consolidados'!$S$2:$S$1000000, MATCH(B201, 'Dados Consolidados'!$B$2:$B$1000000, 0))) -> #N/A | AA201: =INT(INDEX('Dados Consolidados'!$T$2:$T$1000000, MATCH(E201, 'Dados Consolidados'!$E$2:$E$1000000, 0))) -> #N/A | AB201: =INT(INDEX('Dados Consolidados'!$U$2:$U$1000000, MATCH(H201, 'Dados Consolidados'!$H$2:$H$1000000, 0))) -> #N/A | AC201: =INT(INDEX('Dados Consolidados'!$V$2:$V$1000000, MATCH(J201, 'Dados Consolidados'!$J$2:$J$1000000, 0))) -> #N/A | AD201: =INT(INDEX('Dados Consolidados'!$X$2:$X$1000000, MATCH(K201, 'Dados Consolidados'!$K$2:$K$1000000, 0))) -> #N/A | AE201: =INT(INDEX('Dados Consolidados'!$W$2:$W$1000000, MATCH(P201, 'Dados Consolidados'!$P$2:$P$1000000, 0))) -> #N/A

Sheet Cadastro de Pedidos
A1: Cadastros Básicos > Pedido | Q1: Atributos | Y1: Banco de Dados
A2: Cadastro de Pedidos
A3: Seção | B3: Espécie | C3: Descrição | D3: Descrição Reduzida | E3: Marca | F3: Referência do Fornecedor | G3: Código Original | H3: Comprador | I3: Produto Ativo? | J3: Unidade | K3: Classificação Fiscal | L3: Origem | M3: Valor de Venda | N3: % ICMS | O3: % IPI | P3: Etiqueta Padrão | Y3: Seção | Z3: Espécie | AA3: Marca | AB3: Comprador | AC3: Unidade | AD3: Etiqueta Padrão
Y4: Os valores abaixo servem para consolidar os dados selecionados nos menus suspensos das tabelas acima e garantir uma integração eficiente com o banco de dados. Por esse motivo, essas células estão protegidas.

Sheet Cadastro de Marcas
A1: Cadastros Básicos > Marca
A2: Cadastro de Marcas
A3: Nome
A4: Obrigatório
A5: Máximo 50 caracteres.

Sheet Dados Consolidados
A2: 1 - BEBE | B2: 1 - MACACAO | E2: 1 - ABRANGE | H2: 3 - SUELI IVANOW | J2: 1 - PC | K2: 01012100 - CAVALOS REPRODUTORES DE RA?A PURA | P2: 5 - Remarcacao Zebra | R2: 1 | S2: 1 | T2: 1 | U2: 3 | V2: 1 | W2: 5 | X2: 39
A3: 2 - BOLSA CINTO ACESS | B3: 2 - BERCO | E3: 2 - ACILIO BREDA | H3: 4 - LUCIA MARIANO | J3: 2 - METRO | K3: 01012900 - OUTROS CAVALOS VIVOS | P3: 10 - ETIQUETA DESENV | R3: 2 | S3: 2 | T3: 2 | U3: 4 | V3: 2 | W3: 10 | X3: 41
A4: 3 - BRINQUEDO | B4: 3 - ENXOVAL | E4: 3 - ACOFF | H4: 5 - NATALIA CAROLINE | J4: 3 - PAR | K4: 01013000 - ASININOS VIVOS | P4: 14 - ETIQUETA ADESIVA CODIGO NEXTT ZEBRA | R4: 3 | S4: 3 | T4: 3 | U4: 5 | V4: 3 | W4: 14 | X4: 42
A5: 4 - CAMA MESA BANHO | B5: 4 - HIGIENE | E5: 4 - ADG CONFECCOES | H5: 6 - ERIK WALLISON | J5: 4 - 1 | K5: 01019000 - OUTROS MUARES VIVOS | P5: 16 - ETIQUETA ADESIVA 2 CODIGO NEXTT ZEBRA | R5: 4 | S5: 4 | T5: 4 | U5: 6 | V5: 4 | W5: 16 | X5: 46
A6: 5 - CARRINHO BEBE ACESS | B6: 5 - ACESSORIO | E6: 5 - ADK | H6: 9 - HELOISA FERNANDES PEREIRA | J6: 5 - N | K6: 01022110 - BOVINOS DOM?ST.REPROD.D/RA?A PURA,PRENHES OU C/CRIA AO | P6: 17 - Etiqueta Adesiva GC420t | R6: 5 | S6: 5 | T6: 5 | U6: 9 | V6: 5 | W6: 17 | X6: 47
A7: 6 - CARTAO PRESENTE | B7: 1 - BIJOUTERIA | E7: 6 - AGANESTAR | H7: 10 - LAIS GONCALVES OLIVEIRA | J7: 6 - PE A | K7: 01022190 - OUTROS BOVINOS REPRODUTORES DE RA?A PURA | P7: 18 - ETIQUETA VOLUME TRANSFERÊNCIA | R7: 6 | S7: 1 | T7: 6 | U7: 10 | V7: 6 | W7: 18 | X7: 55
A8: 7 - ELETROELETRONICO | B8: 2 - SOMBRINHA GUARDA CHUV | E8: 7 - AHVAZ | H8: 12 - ANDREIA DE ARAUJO VALENTE | J8: 7 - U | K8: 01022911 - OUTROS BOVINOS P/REPRODU??O, PRENHES OU C/CRIA AO P? | P8: 19 - ETIQUETA PADRÃO PACK DE PRODUTOS | R8: 7 | S8: 2 | T8: 7 | U8: 12 | V8: 7 | W8: 19 | X8: 57
A9: 8 - ELETROPORTATEIS | B9: 3 - ACESSORIO FEMININO | E9: 8 - AISTHY | H9: 13 - ANGELICA RAIANE | J9: 8 - UM | K9: 01022919 - OUTROS BOVINOS DOM?STICOS PARA REPRODU??O | P9: 20 - Etiqueta SKINA TAG 2 COL - TLP2844 | R9: 8 | S9: 3 | T9: 8 | U9: 13 | V9: 8 | W9: 20 | X9: 60
A10: 9 - EVENTUAIS | B10: 4 - BOLSA | E10: 9 - AKIYOSHI | H10: 14 - FRANCIELE CRISTINA SANTOS DE GODOY | J10: 9 - UN | K10: 01022990 - OUTROS BOVINOS DOM?STICOS VIVOS | P10: 21 - ETQ - SKINA 34X23 - TLP2844 | R10: 9 | S10: 4 | T10: 9 | U10: 14 | V10: 9 | W10: 21 | X10: 64
A11: 10 - FEMININO CLASSICO | B11: 1 - BONECA | E11: 10 - ANDREZA | H11: 16 - SUZIANI ALVES FERNANDES | K11: 01023110 - B?FALOS REPROD.DE RA?A PURA, PRENHES OU C/CRIA AO P? | P11: 22 - Etq - Remarcacao - SKINA - TLP2844 | R11: 10 | S11: 1 | T11: 10 | U11: 16 | W11: 22 | X11: 65
A12: 11 - FEMININO CONTEMPORANEO | B12: 2 - DIVERSOS | E12: 11 - ANDRIMALHAS | H12: 17 - CAROLINE TEIXEIRA DA SILVA | K12: 01023190 - OUTROS B?FALOS REPRODUTORES DE RA?A PURA | P12: 23 - Etiqueta SKINA TAG 2 COL - GC420T | R12: 11 | S12: 2 | T12: 11 | U12: 17 | W12: 23 | X12: 67
A13: 12 - FEMININO JOVEM | B13: 3 - PELUCIA | E13: 12 - ANGERO MALHAS | H13: 18 - CLAUDIA LEMES PEREIRA | K13: 01023911 - OUTROS B?FALOS P/REPRODU??O, PRENHES OU C/CRIA AO P? | R13: 12 | S13: 3 | T13: 12 | U13: 18 | X13: 69
A14: 13 - GINASTICA FEMININA | B14: 4 - CHAO | E14: 13 - ANT SHOK | H14: 19 - VENDEDOR LOJA 01 | K14: 01023919 - OUTROS B?FALOS PARA REPRODU??O | R14: 13 | S14: 4 | T14: 13 | U14: 19 | X14: 70
A15: 14 - INFANTIL MENINA | B15: 5 - ELETRONICO | E15: 15 - AQUARELA ME | H15: 20 - VENDEDOR LOJA 02 | K15: 01023990 - OUTROS B?FALOS VIVOS | R15: 14 | S15: 5 | T15: 15 | U15: 20 | X15: 77
A16: 15 - INFANTIL MENINO | B16: 1 - CAMA | E16: 16 - ATUAL | H16: 21 - IVANI PEREZ RUIVO | K16: 01029000 - OUTROS ANIMAIS VIVOS DA ESP?CIE BOVINA | R16: 15 | S16: 1 | T16: 16 | U16: 21 | X16: 79
A17: 16 - INVERNO FEM CONT CLASS | B17: 2 - BANHO | E17: 17 - AVAL TEXTIL FARAELI | H17: 22 - PRISCILA FERNANDES | K17: 01031000 - Reprodutores de raça pura | R17: 16 | S17: 2 | T17: 17 | U17: 22 | X17: 80
A18: 17 - INVERNO FEMININO JOVEM | B18: 3 - MESA | E18: 18 - AYONA | H18: 24 - HELEN CHOBBA | K18: 01039100 - De peso inferior a 50kg | R18: 17 | S18: 3 | T18: 18 | U18: 24 | X18: 81
A19: 18 - JEANS FEMININO JOVEM | B19: 1 - CARRINHO | E19: 20 - BACCI | H19: 27 - ALISON SILVA | K19: 01039200 - De peso igual ou superior a 50kg | R19: 18 | S19: 1 | T19: 20 | U19: 27 | X19: 82
A20: 19 - JEANS FEMININO TG | B20: 2 - ANDADOR | E20: 21 - BANDEIRANTE | H20: 30 - ROSILENE ALVES LINS | K20: 01041011 - Prenhes ou com cria ao pé | R20: 19 | S20: 2 | T20: 21 | U20: 30 | X20: 93
A21: 20 - JEANS MASCULINO | B21: 3 - CADEIRA | E21: 22 - BDB FERRAMENTAS | H21: 34 - CONTABILIDADE | K21: 01041019 - Outros | R21: 20 | S21: 3 | T21: 22 | U21: 34 | X21: 100
A22: 21 - JUVENIL MENINA | B22: 1 - CARTAO PRESENTE | E22: 23 - BEACH E COUNTRY | H22: 35 - ELIETE | K22: 01051110 - De linhas puras ou híbridas, para reprodução | R22: 21 | S22: 1 | T22: 23 | U22: 35 | X22: 103
A23: 22 - JUVENIL MENINO | B23: 1 - RADIO | E23: 24 - BELLOT | H23: 37 - CLAUDINEY OLIVEIRA | K23: 01051200 - Peruas e perus | R23: 22 | S23: 1 | T23: 24 | U23: 37 | X23: 105
A24: 23 - LINGERIE | B24: 2 - TELEFONE | E24: 25 - BESTIE | H24: 38 - ANDREIA DE ARAUJO VALENTE | K24: 01051300 - PATOS DOM?STICOS, VIVOS DE PESO INFERIOR A 185G | R24: 23 | S24: 2 | T24: 25 | U24: 38 | X24: 110
... A32: 31 - PRIM PASSOS MENINA | B32: 3 - BLUSA TOP CAMISETA | E32: 38 - BRANDILI | H32: 54 - ANA CRISTINA ALVES | K32: 01062000 - Répteis (incluídas as serpentes e as tartarugas marinhas) | R32: 31 | S32: 3 | T32: 38 | U32: 54 | X32: 125
A33: 32 - PRIM PASSOS MENINO | B33: 4 - SHORTS BERMUDA | E33: 39 - BRASCOL | K33: 01063100 - Aves de rapina | R33: 32 | S33: 4 | T33: 39 | U33: 7 | X33: 128
A34: 33 - PRODUTOS DIVERSOS | B34: 5 - VESTIDO MACACAO | E34: 40 - BRASKIT | K34: 01063200 - Psitaciformes (incluídos os papagaios, os periquitos, as araras e as cacatuas) | R34: 33 | S34: 5 | T34: 40 | U34: 11 | X34: 129
A35: 34 - TEEN FEMININO | B35: 6 - SOBREPOSICAO | E35: 41 - BRILHANTE | K35: 01063310 - AVESTRUZES (STRUTHIO CAMELUS) PARA REPRODU??O | R35: 34 | S35: 6 | T35: 41 | U35: 15 | X35: 130
A36: 35 - TEEN MASCULINO | B36: 7 - CONJUNTO | E36: 42 - BRILHO TEEN | K36: 01063390 - OUTROS AVESTRUZES VIVOS | R36: 35 | S36: 7 | T36: 42 | U36: 23 | X36: 131
A37: 36 - UTILID PARA O LAR | B37: 8 - BLUSA M L | E37: 43 - BROOKS | K37: 01063900 - OUTRAS AVES VIVAS | R37: 36 | S37: 8 | T37: 43 | U37: 25 | X37: 144
A38: 37 - CALÇADOS | B38: 1 - SAIA | E38: 44 - BUBA | K38: 01064100 - ABELHAS VIVAS | R38: 37 | S38: 1 | T38: 44 | U38: 26 | X38: 145
B39: 2 - CALCA | E39: 45 - BUDDEMEYER | K39: 01064900 - OUTROS INSETOS VIVOS | S39: 2 | T39: 45 | U39: 28 | X39: 146
B40: 3 - BLUSA TOP CAMISETA | E40: 46 - CADENCE | K40: 02011000 - Carcaças e meias-carcaças | S40: 3 | T40: 46 | U40: 29 | X40: 147
B41: 4 - SHORTS BERMUDA | E41: 47 - CAEDU | K41: 02012010 - Quartos dianteiros | S41: 4 | T41: 47 | U41: 31 | X41: 160
B42: 5 - VESTIDO MACACAO | E42: 48 - CALESITA | K42: 02012020 - Quartos traseiros | S42: 5 | T42: 48 | U42: 32 | X42: 162
B43: 6 - SOBREPOSICAO | E43: 49 - CAMELO | K43: 02012090 - Outras | S43: 6 | T43: 49 | U43: 33 | X43: 175
B44: 7 - BLUSA M L | E44: 50 - CAMESA | K44: 02013000 - Desossadas | S44: 7 | T44: 50 | U44: 36 | X44: 194
B45: 1 - CALCA | E45: 52 - CAMPCENTER | K45: 02031200 - Pernas, pás e respectivos pedaços, não desossados | S45: 1 | T45: 52 | U45: 40 | X45: 198
B46: 2 - BLUSA TOP CAMISETA | E46: 53 - CANDIDE | K46: 02041000 - Carcaças e meias-carcaças de cordeiro, frescas ou refrigeradas | S46: 2 | T46: 53 | U46: 41 | X46: 199
B47: 3 - SOBREPOSICAO | E47: 54 - CAROLINA CONFECCOES | K47: 02042200 - Outras peças não desossadas | S47: 3 | T47: 54 | U47: 49 | X47: 200
B48: 4 - VESTIDO MACACAO | E48: 55 - CENSATO | K48: 02043000 - Carcaças e meias-carcaças de cordeiro, congeladas | S48: 4 | T48: 55 | U48: 50 | X48: 203
...
